[2023-03-07T15:29:54.754+0000] {taskinstance.py:1083} INFO - Dependencies all met for <TaskInstance: http_request_dag.server_node manual__2023-03-07T15:29:52.927324+00:00 [queued]>
[2023-03-07T15:29:54.780+0000] {taskinstance.py:1083} INFO - Dependencies all met for <TaskInstance: http_request_dag.server_node manual__2023-03-07T15:29:52.927324+00:00 [queued]>
[2023-03-07T15:29:54.781+0000] {taskinstance.py:1279} INFO - 
--------------------------------------------------------------------------------
[2023-03-07T15:29:54.781+0000] {taskinstance.py:1280} INFO - Starting attempt 1 of 2
[2023-03-07T15:29:54.781+0000] {taskinstance.py:1281} INFO - 
--------------------------------------------------------------------------------
[2023-03-07T15:29:54.791+0000] {taskinstance.py:1300} INFO - Executing <Task(SimpleHttpOperator): server_node> on 2023-03-07 15:29:52.927324+00:00
[2023-03-07T15:29:54.801+0000] {standard_task_runner.py:55} INFO - Started process 6622 to run task
[2023-03-07T15:29:54.807+0000] {standard_task_runner.py:82} INFO - Running: ['***', 'tasks', 'run', 'http_request_dag', 'server_node', 'manual__2023-03-07T15:29:52.927324+00:00', '--job-id', '158', '--raw', '--subdir', 'DAGS_FOLDER/httpDag.py', '--cfg-path', '/tmp/tmpupzmb2g7']
[2023-03-07T15:29:54.809+0000] {standard_task_runner.py:83} INFO - Job 158: Subtask server_node
[2023-03-07T15:29:54.939+0000] {task_command.py:388} INFO - Running <TaskInstance: http_request_dag.server_node manual__2023-03-07T15:29:52.927324+00:00 [running]> on host 8e82f4110add
[2023-03-07T15:29:55.013+0000] {taskinstance.py:1509} INFO - Exporting the following env vars:
AIRFLOW_CTX_DAG_OWNER=***
AIRFLOW_CTX_DAG_ID=http_request_dag
AIRFLOW_CTX_TASK_ID=server_node
AIRFLOW_CTX_EXECUTION_DATE=2023-03-07T15:29:52.927324+00:00
AIRFLOW_CTX_TRY_NUMBER=1
AIRFLOW_CTX_DAG_RUN_ID=manual__2023-03-07T15:29:52.927324+00:00
[2023-03-07T15:29:55.015+0000] {http.py:123} INFO - Calling HTTP method
[2023-03-07T15:29:55.028+0000] {base.py:73} INFO - Using connection ID 'nome_conexao_pokemon_2' for task execution.
[2023-03-07T15:29:56.313+0000] {http.py:163} ERROR - HTTP error: Not Found
[2023-03-07T15:29:56.319+0000] {http.py:164} ERROR - <!DOCTYPE html>
<html lang="en">
<head>
<meta charset="utf-8">
<title>Error</title>
</head>
<body>
<pre>Cannot GET /api/v2/pokemon/ditto/https:/pokeapi.co/api/v2/pokemon/ditto</pre>
<script defer src="https://static.cloudflareinsights.com/beacon.min.js/vaafb692b2aea4879b33c060e79fe94621666317369993" integrity="sha512-0ahDYl866UMhKuYcW078ScMalXqtFJggm7TmlUtp0UlD4eQk0Ixfnm5ykXKvGJNFjLMoortdseTfsRT8oCfgGA==" data-cf-beacon='{"rayId":"7a43e076bb3b0103","version":"2023.2.0","r":1,"token":"9fbcf60ab0bc4d7d9c24cc0a2b3b7af0","si":100}' crossorigin="anonymous"></script>
</body>
</html>

[2023-03-07T15:29:56.480+0000] {taskinstance.py:1768} ERROR - Task failed with exception
Traceback (most recent call last):
  File "/home/airflow/.local/lib/python3.7/site-packages/airflow/providers/http/hooks/http.py", line 161, in check_response
    response.raise_for_status()
  File "/home/airflow/.local/lib/python3.7/site-packages/requests/models.py", line 1021, in raise_for_status
    raise HTTPError(http_error_msg, response=self)
requests.exceptions.HTTPError: 404 Client Error: Not Found for url: https://pokeapi.co/api/v2/pokemon/ditto/https:/pokeapi.co/api/v2/pokemon/ditto

During handling of the above exception, another exception occurred:

Traceback (most recent call last):
  File "/home/airflow/.local/lib/python3.7/site-packages/airflow/providers/http/operators/http.py", line 125, in execute
    response = http.run(self.endpoint, self.data, self.headers, self.extra_options)
  File "/home/airflow/.local/lib/python3.7/site-packages/airflow/providers/http/hooks/http.py", line 151, in run
    return self.run_and_check(session, prepped_request, extra_options)
  File "/home/airflow/.local/lib/python3.7/site-packages/airflow/providers/http/hooks/http.py", line 204, in run_and_check
    self.check_response(response)
  File "/home/airflow/.local/lib/python3.7/site-packages/airflow/providers/http/hooks/http.py", line 165, in check_response
    raise AirflowException(str(response.status_code) + ":" + response.reason)
airflow.exceptions.AirflowException: 404:Not Found
[2023-03-07T15:29:56.508+0000] {taskinstance.py:1323} INFO - Marking task as UP_FOR_RETRY. dag_id=http_request_dag, task_id=server_node, execution_date=20230307T152952, start_date=20230307T152954, end_date=20230307T152956
[2023-03-07T15:29:56.596+0000] {standard_task_runner.py:105} ERROR - Failed to execute job 158 for task server_node (404:Not Found; 6622)
[2023-03-07T15:29:56.721+0000] {local_task_job.py:208} INFO - Task exited with return code 1
[2023-03-07T15:29:56.837+0000] {taskinstance.py:2578} INFO - 0 downstream tasks scheduled from follow-on schedule check
