[2023-03-07T15:15:02.074+0000] {taskinstance.py:1083} INFO - Dependencies all met for <TaskInstance: http_request_dag.http_request_dag scheduled__2023-03-07T15:12:57.395619+00:00 [queued]>
[2023-03-07T15:15:02.089+0000] {taskinstance.py:1083} INFO - Dependencies all met for <TaskInstance: http_request_dag.http_request_dag scheduled__2023-03-07T15:12:57.395619+00:00 [queued]>
[2023-03-07T15:15:02.090+0000] {taskinstance.py:1279} INFO - 
--------------------------------------------------------------------------------
[2023-03-07T15:15:02.090+0000] {taskinstance.py:1280} INFO - Starting attempt 2 of 2
[2023-03-07T15:15:02.092+0000] {taskinstance.py:1281} INFO - 
--------------------------------------------------------------------------------
[2023-03-07T15:15:02.132+0000] {taskinstance.py:1300} INFO - Executing <Task(SimpleHttpOperator): http_request_dag> on 2023-03-07 15:12:57.395619+00:00
[2023-03-07T15:15:02.145+0000] {standard_task_runner.py:55} INFO - Started process 5718 to run task
[2023-03-07T15:15:02.152+0000] {standard_task_runner.py:82} INFO - Running: ['***', 'tasks', 'run', 'http_request_dag', 'http_request_dag', 'scheduled__2023-03-07T15:12:57.395619+00:00', '--job-id', '145', '--raw', '--subdir', 'DAGS_FOLDER/httpDag.py', '--cfg-path', '/tmp/tmp6x5yeoth']
[2023-03-07T15:15:02.154+0000] {standard_task_runner.py:83} INFO - Job 145: Subtask http_request_dag
[2023-03-07T15:15:02.315+0000] {task_command.py:388} INFO - Running <TaskInstance: http_request_dag.http_request_dag scheduled__2023-03-07T15:12:57.395619+00:00 [running]> on host 8e82f4110add
[2023-03-07T15:15:02.530+0000] {taskinstance.py:1509} INFO - Exporting the following env vars:
AIRFLOW_CTX_DAG_OWNER=***
AIRFLOW_CTX_DAG_ID=http_request_dag
AIRFLOW_CTX_TASK_ID=http_request_dag
AIRFLOW_CTX_EXECUTION_DATE=2023-03-07T15:12:57.395619+00:00
AIRFLOW_CTX_TRY_NUMBER=2
AIRFLOW_CTX_DAG_RUN_ID=scheduled__2023-03-07T15:12:57.395619+00:00
[2023-03-07T15:15:02.535+0000] {http.py:123} INFO - Calling HTTP method
[2023-03-07T15:15:02.552+0000] {base.py:73} INFO - Using connection ID 'nome_conexao_http' for task execution.
[2023-03-07T15:15:02.565+0000] {http.py:208} WARNING - HTTPConnectionPool(host='localhost', port=3333): Max retries exceeded with url: /http://localhost:3333/ (Caused by NewConnectionError('<urllib3.connection.HTTPConnection object at 0xffff7bdb9cd0>: Failed to establish a new connection: [Errno 111] Connection refused')) Tenacity will retry to execute the operation
[2023-03-07T15:15:02.567+0000] {taskinstance.py:1768} ERROR - Task failed with exception
Traceback (most recent call last):
  File "/home/airflow/.local/lib/python3.7/site-packages/urllib3/connection.py", line 175, in _new_conn
    (self._dns_host, self.port), self.timeout, **extra_kw
  File "/home/airflow/.local/lib/python3.7/site-packages/urllib3/util/connection.py", line 95, in create_connection
    raise err
  File "/home/airflow/.local/lib/python3.7/site-packages/urllib3/util/connection.py", line 85, in create_connection
    sock.connect(sa)
ConnectionRefusedError: [Errno 111] Connection refused

During handling of the above exception, another exception occurred:

Traceback (most recent call last):
  File "/home/airflow/.local/lib/python3.7/site-packages/urllib3/connectionpool.py", line 710, in urlopen
    chunked=chunked,
  File "/home/airflow/.local/lib/python3.7/site-packages/urllib3/connectionpool.py", line 398, in _make_request
    conn.request(method, url, **httplib_request_kw)
  File "/home/airflow/.local/lib/python3.7/site-packages/urllib3/connection.py", line 239, in request
    super(HTTPConnection, self).request(method, url, body=body, headers=headers)
  File "/usr/local/lib/python3.7/http/client.py", line 1281, in request
    self._send_request(method, url, body, headers, encode_chunked)
  File "/usr/local/lib/python3.7/http/client.py", line 1327, in _send_request
    self.endheaders(body, encode_chunked=encode_chunked)
  File "/usr/local/lib/python3.7/http/client.py", line 1276, in endheaders
    self._send_output(message_body, encode_chunked=encode_chunked)
  File "/usr/local/lib/python3.7/http/client.py", line 1036, in _send_output
    self.send(msg)
  File "/usr/local/lib/python3.7/http/client.py", line 976, in send
    self.connect()
  File "/home/airflow/.local/lib/python3.7/site-packages/urllib3/connection.py", line 205, in connect
    conn = self._new_conn()
  File "/home/airflow/.local/lib/python3.7/site-packages/urllib3/connection.py", line 187, in _new_conn
    self, "Failed to establish a new connection: %s" % e
urllib3.exceptions.NewConnectionError: <urllib3.connection.HTTPConnection object at 0xffff7bdb9cd0>: Failed to establish a new connection: [Errno 111] Connection refused

During handling of the above exception, another exception occurred:

Traceback (most recent call last):
  File "/home/airflow/.local/lib/python3.7/site-packages/requests/adapters.py", line 499, in send
    timeout=timeout,
  File "/home/airflow/.local/lib/python3.7/site-packages/urllib3/connectionpool.py", line 788, in urlopen
    method, url, error=e, _pool=self, _stacktrace=sys.exc_info()[2]
  File "/home/airflow/.local/lib/python3.7/site-packages/urllib3/util/retry.py", line 592, in increment
    raise MaxRetryError(_pool, url, error or ResponseError(cause))
urllib3.exceptions.MaxRetryError: HTTPConnectionPool(host='localhost', port=3333): Max retries exceeded with url: /http://localhost:3333/ (Caused by NewConnectionError('<urllib3.connection.HTTPConnection object at 0xffff7bdb9cd0>: Failed to establish a new connection: [Errno 111] Connection refused'))

During handling of the above exception, another exception occurred:

Traceback (most recent call last):
  File "/home/airflow/.local/lib/python3.7/site-packages/airflow/providers/http/operators/http.py", line 125, in execute
    response = http.run(self.endpoint, self.data, self.headers, self.extra_options)
  File "/home/airflow/.local/lib/python3.7/site-packages/airflow/providers/http/hooks/http.py", line 151, in run
    return self.run_and_check(session, prepped_request, extra_options)
  File "/home/airflow/.local/lib/python3.7/site-packages/airflow/providers/http/hooks/http.py", line 209, in run_and_check
    raise ex
  File "/home/airflow/.local/lib/python3.7/site-packages/airflow/providers/http/hooks/http.py", line 201, in run_and_check
    response = session.send(prepped_request, **send_kwargs)
  File "/home/airflow/.local/lib/python3.7/site-packages/requests/sessions.py", line 701, in send
    r = adapter.send(request, **kwargs)
  File "/home/airflow/.local/lib/python3.7/site-packages/requests/adapters.py", line 565, in send
    raise ConnectionError(e, request=request)
requests.exceptions.ConnectionError: HTTPConnectionPool(host='localhost', port=3333): Max retries exceeded with url: /http://localhost:3333/ (Caused by NewConnectionError('<urllib3.connection.HTTPConnection object at 0xffff7bdb9cd0>: Failed to establish a new connection: [Errno 111] Connection refused'))
[2023-03-07T15:15:02.600+0000] {taskinstance.py:1323} INFO - Marking task as FAILED. dag_id=http_request_dag, task_id=http_request_dag, execution_date=20230307T151257, start_date=20230307T151502, end_date=20230307T151502
[2023-03-07T15:15:02.619+0000] {standard_task_runner.py:105} ERROR - Failed to execute job 145 for task http_request_dag (HTTPConnectionPool(host='localhost', port=3333): Max retries exceeded with url: /http://localhost:3333/ (Caused by NewConnectionError('<urllib3.connection.HTTPConnection object at 0xffff7bdb9cd0>: Failed to establish a new connection: [Errno 111] Connection refused')); 5718)
[2023-03-07T15:15:02.654+0000] {local_task_job.py:208} INFO - Task exited with return code 1
[2023-03-07T15:15:02.695+0000] {taskinstance.py:2578} INFO - 0 downstream tasks scheduled from follow-on schedule check
